Traceback (most recent call last):
  File "/home/noah/ssp2/sendData.py", line 29, in <module>
    sys.exit(main(sys.argv))
             ^^^^^^^^^^^^^^
  File "/home/noah/ssp2/sendData.py", line 19, in main
    temperature_f = str(tempSensor.temperature * (9 / 5) + 32) # converts celcius reading to F
                        ^^^^^^^^^^^^^^^^^^^^^^
  File "/home/noah/env/lib/python3.11/site-packages/adafruit_dht.py", line 273, in temperature
    self.measure()
  File "/home/noah/env/lib/python3.11/site-packages/adafruit_dht.py", line 229, in measure
    raise RuntimeError("A full buffer was not returned. Try again.")
RuntimeError: A full buffer was not returned. Try again.
Lost access to message queue
Sent data to server at: 2025-02-27 15:04:01.398572
Sent data to server at: 2025-02-27 15:05:02.024960
Sent data to server at: 2025-02-27 15:06:03.685813
Sent data to server at: 2025-02-27 15:10:01.417688
Sent data to server at: 2025-02-27 15:11:01.902831
Sent data to server at: 2025-02-27 15:12:01.371972
Traceback (most recent call last):
  File "/usr/lib/python3/dist-packages/urllib3/connection.py", line 174, in _new_conn
    conn = connection.create_connection(
           ^^^^^^^^^^^^^^^^^^^^^^^^^^^^^
  File "/usr/lib/python3/dist-packages/urllib3/util/connection.py", line 96, in create_connection
    raise err
  File "/usr/lib/python3/dist-packages/urllib3/util/connection.py", line 86, in create_connection
    sock.connect(sa)
ConnectionRefusedError: [Errno 111] Connection refused

During handling of the above exception, another exception occurred:

Traceback (most recent call last):
  File "/usr/lib/python3/dist-packages/urllib3/connectionpool.py", line 705, in urlopen
    httplib_response = self._make_request(
                       ^^^^^^^^^^^^^^^^^^^
  File "/usr/lib/python3/dist-packages/urllib3/connectionpool.py", line 400, in _make_request
    conn.request(method, url, **httplib_request_kw)
  File "/usr/lib/python3/dist-packages/urllib3/connection.py", line 239, in request
    super(HTTPConnection, self).request(method, url, body=body, headers=headers)
  File "/usr/lib/python3.11/http/client.py", line 1282, in request
    self._send_request(method, url, body, headers, encode_chunked)
  File "/usr/lib/python3.11/http/client.py", line 1328, in _send_request
    self.endheaders(body, encode_chunked=encode_chunked)
  File "/usr/lib/python3.11/http/client.py", line 1277, in endheaders
    self._send_output(message_body, encode_chunked=encode_chunked)
  File "/usr/lib/python3.11/http/client.py", line 1037, in _send_output
    self.send(msg)
  File "/usr/lib/python3.11/http/client.py", line 975, in send
    self.connect()
  File "/usr/lib/python3/dist-packages/urllib3/connection.py", line 205, in connect
    conn = self._new_conn()
           ^^^^^^^^^^^^^^^^
  File "/usr/lib/python3/dist-packages/urllib3/connection.py", line 186, in _new_conn
    raise NewConnectionError(
urllib3.exceptions.NewConnectionError: <urllib3.connection.HTTPConnection object at 0x7fff6cbf8290>: Failed to establish a new connection: [Errno 111] Connection refused

During handling of the above exception, another exception occurred:

Traceback (most recent call last):
  File "/usr/lib/python3/dist-packages/requests/adapters.py", line 489, in send
    resp = conn.urlopen(
           ^^^^^^^^^^^^^
  File "/usr/lib/python3/dist-packages/urllib3/connectionpool.py", line 789, in urlopen
    retries = retries.increment(
              ^^^^^^^^^^^^^^^^^^
  File "/usr/lib/python3/dist-packages/urllib3/util/retry.py", line 594, in increment
    raise MaxRetryError(_pool, url, error or ResponseError(cause))
urllib3.exceptions.MaxRetryError: HTTPConnectionPool(host='localhost', port=3000): Max retries exceeded with url: /data (Caused by NewConnectionError('<urllib3.connection.HTTPConnection object at 0x7fff6cbf8290>: Failed to establish a new connection: [Errno 111] Connection refused'))

During handling of the above exception, another exception occurred:

Traceback (most recent call last):
  File "/home/noah/ssp2/sendData.py", line 31, in <module>
    sys.exit(main(sys.argv))
             ^^^^^^^^^^^^^^
  File "/home/noah/ssp2/sendData.py", line 25, in main
    requests.post(url, sensorData) #add error handling here (if server is down)
    ^^^^^^^^^^^^^^^^^^^^^^^^^^^^^^
  File "/usr/lib/python3/dist-packages/requests/api.py", line 115, in post
    return request("post", url, data=data, json=json, **kwargs)
           ^^^^^^^^^^^^^^^^^^^^^^^^^^^^^^^^^^^^^^^^^^^^^^^^^^^^
  File "/usr/lib/python3/dist-packages/requests/api.py", line 59, in request
    return session.request(method=method, url=url, **kwargs)
           ^^^^^^^^^^^^^^^^^^^^^^^^^^^^^^^^^^^^^^^^^^^^^^^^^
  File "/usr/lib/python3/dist-packages/requests/sessions.py", line 587, in request
    resp = self.send(prep, **send_kwargs)
           ^^^^^^^^^^^^^^^^^^^^^^^^^^^^^^
  File "/usr/lib/python3/dist-packages/requests/sessions.py", line 701, in send
    r = adapter.send(request, **kwargs)
        ^^^^^^^^^^^^^^^^^^^^^^^^^^^^^^^
  File "/usr/lib/python3/dist-packages/requests/adapters.py", line 565, in send
    raise ConnectionError(e, request=request)
requests.exceptions.ConnectionError: HTTPConnectionPool(host='localhost', port=3000): Max retries exceeded with url: /data (Caused by NewConnectionError('<urllib3.connection.HTTPConnection object at 0x7fff6cbf8290>: Failed to establish a new connection: [Errno 111] Connection refused'))
Sent data to server at: 2025-02-27 15:14:01.331720
Sent data to server at: 2025-02-27 15:15:01.849910
